Workbook
Name ActiveScenario: Assumptions!$B$3
Name Driver_COGS: Assumptions!$B$32
Name Driver_Marketing: Assumptions!$B$34
Name Driver_OtherOpEx: Assumptions!$B$36
Name Driver_Payroll: Assumptions!$B$33
Name Driver_Utilities: Assumptions!$B$35
Name Rent_Escalation: Assumptions!$B$38
Name ScenarioMult: Assumptions!$C$3
Name Seasonality_Apr: Assumptions!$B$20
Name Seasonality_Aug: Assumptions!$B$24
Name Seasonality_Dec: Assumptions!$B$28
Name Seasonality_Feb: Assumptions!$B$18
Name Seasonality_Jan: Assumptions!$B$17
Name Seasonality_Jul: Assumptions!$B$23
Name Seasonality_Jun: Assumptions!$B$22
Name Seasonality_Mar: Assumptions!$B$19
Name Seasonality_May: Assumptions!$B$21
Name Seasonality_Nov: Assumptions!$B$27
Name Seasonality_Oct: Assumptions!$B$26
Name Seasonality_Sep: Assumptions!$B$25
Name Unit1_Growth: Assumptions!$B$9
Name Unit2_Growth: Assumptions!$B$10
Name Unit3_Growth: Assumptions!$B$11
Name Unit4_Growth: Assumptions!$B$12
Name Unit5_Growth: Assumptions!$B$13

Sheet Assumptions
A1: Model Assumptions & Drivers
A3: Selected Scenario: | B3: Base | C3: =HLOOKUP(ActiveScenario, B5:D6, 2, FALSE) -> 0
A5: Scenario Multipliers | B5: Base | C5: Upside | D5: Downside
A6: Multiplier | B6: 1 | C6: 1.15 | D6: 0.85
A8: Unit Assumptions (Base YoY Growth)
A10: Unit 1 | B10: 0.05
A11: Unit 2 | B11: 0.07
A12: Unit 3 | B12: 0.09
A13: Unit 4 | B13: 0.11
A14: Unit 5 | B14: 0.13
A15: Monthly Seasonality Index
A17: Jan | B17: 0.87096774
A18: Feb | B18: 0.82258065
A19: Mar | B19: 0.91935484
A20: Apr | B20: 0.96774194
A21: May | B21: 1.016129
A22: Jun | B22: 1.0645161
A23: Jul | B23: 1.0645161
A24: Aug | B24: 1.016129
A25: Sep | B25: 0.96774194
A26: Oct | B26: 0.91935484
A27: Nov | B27: 1.1129032
A28: Dec | B28: 1.2580645
A30: Cost Structure & Benchmarks (% of Revenue)
A32: COGS % | B32: 0.4
A33: Payroll % | B33: 0.22
A34: Marketing % | B34: 0.05
A35: Utilities % | B35: 0.02
A36: Other OpEx % | B36: 0.03
A38: Annual Rent Escalation % | B38: 0.03

Sheet Historical Data
A1: Historical Financial Data
C2: 44197 | D2: 44228 | E2: 44256 | F2: 44287 | G2: 44317 | H2: 44348 | I2: 44378 | J2: 44409 | K2: 44440 | L2: 44470 | M2: 44501 | N2: 44531 | O2: 44562 | P2: 44593 | Q2: 44621 | R2: 44652 | S2: 44682 | T2: 44713 | U2: 44743 | V2: 44774 | W2: 44805 | X2: 44835 | Y2: 44866 | Z2: 44896 | AA2: 44927 | AB2: 44958 | AC2: 44986 | AD2: 45017 | AE2: 45047 | AF2: 45078 | AG2: 45108 | AH2: 45139 | AI2: 45170 | AJ2: 45200 | AK2: 45231 | AL2: 45261 | AM2: 45292 | AN2: 45323 | AO2: 45352 | AP2: 45383 | AQ2: 45413 | AR2: 45444 | AS2: 45474 | AT2: 45505 | AU2: 45536 | AV2: 45566 | AW2: 45597 | AX2: 45627 | AY2: 45658 | AZ2: 45689 | BA2: 45717 | BB2: 45748 | BC2: 45778 | BD2: 45809 | BE2: 45839 | BF2: 45870 | BG2: 45901 | BH2: 45931 | BI2: 45962 | BJ2: 45992
A3: Category | B3: Unit | C3: Actual | D3: Actual | E3: Actual | F3: Actual | G3: Actual | H3: Actual | I3: Actual | J3: Actual | K3: Actual | L3: Actual | M3: Actual | N3: Actual | O3: Actual | P3: Actual | Q3: Actual | R3: Actual | S3: Actual | T3: Actual | U3: Actual | V3: Actual | W3: Actual | X3: Actual | Y3: Actual | Z3: Actual | AA3: Actual | AB3: Actual | AC3: Actual | AD3: Actual | AE3: Actual | AF3: Actual | AG3: Actual | AH3: Actual | AI3: Actual | AJ3: Actual | AK3: Actual | AL3: Actual | AM3: Forecast | AN3: Forecast | AO3: Forecast | AP3: Forecast | AQ3: Forecast | AR3: Forecast | AS3: Forecast | AT3: Forecast | AU3: Forecast | AV3: Forecast | AW3: Forecast | AX3: Forecast | AY3: Forecast | AZ3: Forecast | BA3: Forecast | BB3: Forecast | BC3: Forecast | BD3: Forecast | BE3: Forecast | BF3: Forecast | BG3: Forecast | BH3: Forecast | BI3: Forecast | BJ3: Forecast
A4: Revenue | B4: Unit 1 | C4: 199050.98 | D4: 177682.55 | E4: 211863.14 | F4: 220131.56 | G4: 228802.62 | H4: 232496.82 | I4: 242374.46 | J4: 229550.03 | K4: 215411.99 | L4: 216458.34 | M4: 247863.37 | N4: 301135.53 | O4: 213904.06 | P4: 184738.79 | Q4: 229089.29 | R4: 233620.66 | S4: 246300.66 | T4: 243724.57 | U4: 245259.69 | V4: 247575.92 | W4: 233911.81 | X4: 215262.29 | Y4: 287179.62 | Z4: 303029.64 | AA4: 207652.4 | AB4: 207832.31 | AC4: 227875.46 | AD4: 255576.77 | AE4: 256258.71 | AF4: 280275.92 | AG4: 276618.86 | AH4: 259206.88 | AI4: 237037.98 | AJ4: 248240.12 | AK4: 290839.89 | AL4: 324344.51
A5: COGS | B5: Unit 1 | C5: 75766.495 | D5: 69160.402 | E5: 82550.569 | F5: 89666.309 | G5: 92527.748 | H5: 96097.397 | I5: 93783.062 | J5: 90819.729 | K5: 83426.79 | L5: 88794.339 | M5: 98403.303 | N5: 116936.25 | O5: 86140.879 | P5: 70432.133 | Q5: 94772.267 | R5: 92978.725 | S5: 97487.283 | T5: 101649.32 | U5: 100333.5 | V5: 97312.595 | W5: 94223.83 | X5: 86284.31 | Y5: 120169.42 | Z5: 125388.01 | AA5: 85115.227 | AB5: 83462.894 | AC5: 91940.924 | AD5: 106987.05 | AE5: 103600.62 | AF5: 109599.09 | AG5: 108393.36 | AH5: 100212.15 | AI5: 90222.691 | AJ5: 98535.455 | AK5: 115113.05 | AL5: 127058.57
A6: Payroll | B6: Unit 1 | C6: 39535.408 | D6: 36735.702 | E6: 48580.016 | F6: 51239.523 | G6: 51403.308 | H6: 55510.298 | I6: 54933.539 | J6: 54692.182 | K6: 50708.348 | L6: 47139.394 | M6: 50117.489 | N6: 64538.163 | O6: 48647.99 | P6: 41991.236 | Q6: 51319.919 | R6: 49080.841 | S6: 54849.855 | T6: 52363.927 | U6: 59047.579 | V6: 58267.539 | W6: 53742.664 | X6: 44857.075 | Y6: 60097.219 | Z6: 60538.981 | AA6: 47608.294 | AB6: 42164.851 | AC6: 49524.358 | AD6: 52872.609 | AE6: 60839.303 | AF6: 61356.965 | AG6: 61626.291 | AH6: 59255.394 | AI6: 48386.702 | AJ6: 55753.332 | AK6: 64494.621 | AL6: 67118.132
A7: Rent | B7: Unit 1 | C7: 22195.8 | D7: 22195.8 | E7: 22195.8 | F7: 22195.8 | G7: 22195.8 | H7: 22195.8 | I7: 22195.8 | J7: 22195.8 | K7: 22195.8 | L7: 22195.8 | M7: 22195.8 | N7: 22195.8 | O7: 22861.674 | P7: 22861.674 | Q7: 22861.674 | R7: 22861.674 | S7: 22861.674 | T7: 22861.674 | U7: 22861.674 | V7: 22861.674 | W7: 22861.674 | X7: 22861.674 | Y7: 22861.674 | Z7: 22861.674 | AA7: 23527.548 | AB7: 23527.548 | AC7: 23527.548 | AD7: 23527.548 | AE7: 23527.548 | AF7: 23527.548 | AG7: 23527.548 | AH7: 23527.548 | AI7: 23527.548 | AJ7: 23527.548 | AK7: 23527.548 | AL7: 23527.548
A8: Marketing | B8: Unit 1 | C8: 10834.053 | D8: 9059.7943 | E8: 11005.834 | F8: 11844.108 | G8: 11724.656 | H8: 11149.696 | I8: 11162.542 | J8: 11377.726 | K8: 10164.086 | L8: 10642.196 | M8: 13343.18 | N8: 14527.817 | O8: 9886.8338 | P8: 8971.466 | Q8: 12386.465 | R8: 11148.687 | S8: 12678.795 | T8: 10968.874 | U8: 11901.395 | V8: 11895.481 | W8: 10911.181 | X8: 10836.496 | Y8: 14315.416 | Z8: 15734.62 | AA8: 9903.7994 | AB8: 9859.8254 | AC8: 10637.89 | AD8: 12060.065 | AE8: 12961.827 | AF8: 13744.272 | AG8: 12627.353 | AH8: 12322.476 | AI8: 11251.899 | AJ8: 12899.312 | AK8: 15159.362 | AL8: 15075.815
A9: Utilities | B9: Unit 1 | C9: 4377.3224 | D9: 3387.8953 | E9: 4641.1713 | F9: 4324.297 | G9: 4148.6955 | H9: 4505.8546 | I9: 4977.7426 | J9: 4756.9243 | K9: 4334.8945 | L9: 4283.9556 | M9: 5009.7084 | N9: 6134.3677 | O9: 3919.4525 | P9: 3598.4564 | Q9: 4345.5122 | R9: 4955.692 | S9: 4896.7534 | T9: 5345.7798 | U9: 4805.9367 | V9: 5264.882 | W9: 4957.3819 | X9: 4004.4965 | Y9: 5753.0105 | Z9: 6297.941 | AA9: 4450.7044 | AB9: 4011.9607 | AC9: 4302.5085 | AD9: 5327.395 | AE9: 5442.4236 | AF9: 5435.8574 | AG9: 5085.5565 | AH9: 5640.8842 | AI9: 4643.6424 | AJ9: 4982.4288 | AK9: 6209.6762 | AL9: 6714.8268
A10: D&A | B10: Unit 1 | C10: 5000 | D10: 5000 | E10: 5000 | F10: 5000 | G10: 5000 | H10: 5000 | I10: 5000 | J10: 5000 | K10: 5000 | L10: 5000 | M10: 5000 | N10: 5000 | O10: 5000 | P10: 5000 | Q10: 5000 | R10: 5000 | S10: 5000 | T10: 5000 | U10: 5000 | V10: 5000 | W10: 5000 | X10: 5000 | Y10: 5000 | Z10: 5000 | AA10: 5000 | AB10: 5000 | AC10: 5000 | AD10: 5000 | AE10: 5000 | AF10: 5000 | AG10: 5000 | AH10: 5000 | AI10: 5000 | AJ10: 5000 | AK10: 5000 | AL10: 5000
A11: Other OpEx | B11: Unit 1 | C11: 6252.4493 | D11: 5020.3192 | E11: 6408.582 | F11: 6862.5368 | G11: 6491.4277 | H11: 6521.4729 | I11: 7972.4256 | J11: 6909.4134 | K11: 6153.2381 | L11: 7138.2596 | M11: 8128.0635 | N11: 9139.3913 | O11: 6908.2066 | P11: 5197.1166 | Q11: 6568.7295 | R11: 7289.4662 | S11: 7901.3171 | T11: 7832.807 | U11: 7217.2689 | V11: 8003.2928 | W11: 7509.8721 | X11: 7020.5235 | Y11: 9107.0527 | Z11: 9398.1398 | AA11: 6330.1008 | AB11: 6075.7066 | AC11: 7438.0376 | AD11: 8393.6479 | AE11: 7355.5286 | AF11: 8080.9668 | AG11: 8274.6888 | AH11: 7695.9934 | AI11: 7814.3707 | AJ11: 6964.5135 | AK11: 7884.2193 | AL11: 9718.4521
A12: Revenue | B12: Unit 2 | C12: 201995.04 | D12: 199066.52 | E12: 223085.97 | F12: 226456.94 | G12: 244663.68 | H12: 256705.76 | I12: 261244.53 | J12: 241041.2 | K12: 238701.63 | L12: 236641.95 | M12: 274313.65 | N12: 324653.58 | O12: 215588.81 | P12: 202835.83 | Q12: 234585.04 | R12: 248668.01 | S12: 267352.3 | T12: 264167.86 | U12: 272722.27 | V12: 263424.26 | W12: 256943.97 | X12: 227894.96 | Y12: 304734.14 | Z12: 328736.11 | AA12: 224241.66 | AB12: 225866.29 | AC12: 250245.16 | AD12: 269883.44 | AE12: 267680.82 | AF12: 288018.34 | AG12: 289837.98 | AH12: 289123.07 | AI12: 252667.23 | AJ12: 246867.8 | AK12: 296609.29 | AL12: 339425.47
A13: COGS | B13: Unit 2 | C13: 80679.079 | D13: 78612.858 | E13: 88294.674 | F13: 93700.755 | G13: 102073.85 | H13: 98271.239 | I13: 101456.08 | J13: 98066.585 | K13: 94131.004 | L13: 92329.773 | M13: 107479.28 | N13: 127557.05 | O13: 89242.296 | P13: 78186.082 | Q13: 95794.31 | R13: 99992.588 | S13: 104764.78 | T13: 104819.49 | U13: 106429.39 | V13: 106544.72 | W13: 98477.312 | X13: 86647.351 | Y13: 123452.61 | Z13: 127474.31 | AA13: 85848.149 | AB13: 89413.992 | AC13: 95601.345 | AD13: 112127.04 | AE13: 102014.41 | AF13: 116115.92 | AG13: 115221.89 | AH13: 117638.7 | AI13: 99330.085 | AJ13: 95340.755 | AK13: 124360.46 | AL13: 140371.89
A14: Payroll | B14: Unit 2 | C14: 47642.106 | D14: 41607.105 | E14: 44552.216 | F14: 47860.244 | G14: 54225.208 | H14: 54517.284 | I14: 61242.572 | J14: 50606.091 | K14: 57400.84 | L14: 51616.264 | M14: 64477.154 | N14: 67058.081 | O14: 46588.65 | P14: 46404.484 | Q14: 47875.882 | R14: 50688.685 | S14: 64340.904 | T14: 60611.251 | U14: 54491.81 | V14: 56780.603 | W14: 55776.089 | X14: 52584 | Y14: 63700.973 | Z14: 67756.023 | AA14: 45197.793 | AB14: 48978.164 | AC14: 57129.468 | AD14: 54127.963 | AE14: 63780.15 | AF14: 62633.476 | AG14: 60445.898 | AH14: 58440.57 | AI14: 52061.099 | AJ14: 59031.773 | AK14: 67058.588 | AL14: 74922.957
A15: Rent | B15: Unit 2 | C15: 23505.9 | D15: 23505.9 | E15: 23505.9 | F15: 23505.9 | G15: 23505.9 | H15: 23505.9 | I15: 23505.9 | J15: 23505.9 | K15: 23505.9 | L15: 23505.9 | M15: 23505.9 | N15: 23505.9 | O15: 24211.077 | P15: 24211.077 | Q15: 24211.077 | R15: 24211.077 | S15: 24211.077 | T15: 24211.077 | U15: 24211.077 | V15: 24211.077 | W15: 24211.077 | X15: 24211.077 | Y15: 24211.077 | Z15: 24211.077 | AA15: 24916.254 | AB15: 24916.254 | AC15: 24916.254 | AD15: 24916.254 | AE15: 24916.254 | AF15: 24916.254 | AG15: 24916.254 | AH15: 24916.254 | AI15: 24916.254 | AJ15: 24916.254 | AK15: 24916.254 | AL15: 24916.254
... A43: Other OpEx | B43: Unit 5 | C43: 3780.663 | D43: 4558.3158 | E43: 4345.7298 | F43: 5165.1827 | G43: 5046.5651 | H43: 5965.5814 | I43: 5704.6208 | J43: 5457.7585 | K43: 4671.3829 | L43: 5122.7243 | M43: 5766.3974 | N43: 6239.8965 | O43: 4560.489 | P43: 4539.4522 | Q43: 5437.7063 | R43: 5170.1489 | S43: 5136.1841 | T43: 5801.543 | U43: 5828.5784 | V43: 5304.6382 | W43: 4736.0768 | X43: 4691.2634 | Y43: 5709.6415 | Z43: 6815.1442 | AA43: 4738.432 | AB43: 4302.6854 | AC43: 4603.099 | AD43: 6073.3695 | AE43: 5489.6193 | AF43: 5777.3372 | AG43: 6532.4117 | AH43: 5220.0265 | AI43: 5811.2438 | AJ43: 5446.6849 | AK43: 5641.2849 | AL43: 6973.8887

Sheet Revenue Forecast
A1: Revenue Projections
C2: 44197 | D2: 44228 | E2: 44256 | F2: 44287 | G2: 44317 | H2: 44348 | I2: 44378 | J2: 44409 | K2: 44440 | L2: 44470 | M2: 44501 | N2: 44531 | O2: 44562 | P2: 44593 | Q2: 44621 | R2: 44652 | S2: 44682 | T2: 44713 | U2: 44743 | V2: 44774 | W2: 44805 | X2: 44835 | Y2: 44866 | Z2: 44896 | AA2: 44927 | AB2: 44958 | AC2: 44986 | AD2: 45017 | AE2: 45047 | AF2: 45078 | AG2: 45108 | AH2: 45139 | AI2: 45170 | AJ2: 45200 | AK2: 45231 | AL2: 45261 | AM2: 45292 | AN2: 45323 | AO2: 45352 | AP2: 45383 | AQ2: 45413 | AR2: 45444 | AS2: 45474 | AT2: 45505 | AU2: 45536 | AV2: 45566 | AW2: 45597 | AX2: 45627 | AY2: 45658 | AZ2: 45689 | BA2: 45717 | BB2: 45748 | BC2: 45778 | BD2: 45809 | BE2: 45839 | BF2: 45870 | BG2: 45901 | BH2: 45931 | BI2: 45962 | BJ2: 45992
A3: Category | B3: Unit | C3: Actual | D3: Actual | E3: Actual | F3: Actual | G3: Actual | H3: Actual | I3: Actual | J3: Actual | K3: Actual | L3: Actual | M3: Actual | N3: Actual | O3: Actual | P3: Actual | Q3: Actual | R3: Actual | S3: Actual | T3: Actual | U3: Actual | V3: Actual | W3: Actual | X3: Actual | Y3: Actual | Z3: Actual | AA3: Actual | AB3: Actual | AC3: Actual | AD3: Actual | AE3: Actual | AF3: Actual | AG3: Actual | AH3: Actual | AI3: Actual | AJ3: Actual | AK3: Actual | AL3: Actual | AM3: Forecast | AN3: Forecast | AO3: Forecast | AP3: Forecast | AQ3: Forecast | AR3: Forecast | AS3: Forecast | AT3: Forecast | AU3: Forecast | AV3: Forecast | AW3: Forecast | AX3: Forecast | AY3: Forecast | AZ3: Forecast | BA3: Forecast | BB3: Forecast | BC3: Forecast | BD3: Forecast | BE3: Forecast | BF3: Forecast | BG3: Forecast | BH3: Forecast | BI3: Forecast | BJ3: Forecast
A4: Revenue | B4: Unit 1 | C4: ='Historical Data'!C4 -> 0 | D4: ='Historical Data'!D4 -> 0 | E4: ='Historical Data'!E4 -> 0 | F4: ='Historical Data'!F4 -> 0 | G4: ='Historical Data'!G4 -> 0 | H4: ='Historical Data'!H4 -> 0 | I4: ='Historical Data'!I4 -> 0 | J4: ='Historical Data'!J4 -> 0 | ... AL4: ='Historical Data'!AL4 -> 0 | AM4: =AA4*(1+Unit1_Growth)*ScenarioMult -> 0 | AN4: =AB4*(1+Unit1_Growth)*ScenarioMult -> 0 | AO4: =AC4*(1+Unit1_Growth)*ScenarioMult -> 0 | AP4: =AD4*(1+Unit1_Growth)*ScenarioMult -> 0 | AQ4: =AE4*(1+Unit1_Growth)*ScenarioMult -> 0 | AR4: =AF4*(1+Unit1_Growth)*ScenarioMult -> 0 | AS4: =AG4*(1+Unit1_Growth)*ScenarioMult -> 0 | AT4: =AH4*(1+Unit1_Growth)*ScenarioMult -> 0 | ... BJ4: =AX4*(1+Unit1_Growth)*ScenarioMult -> 0
A5: Revenue | B5: Unit 2 | C5: ='Historical Data'!C5 -> 0 | D5: ='Historical Data'!D5 -> 0 | E5: ='Historical Data'!E5 -> 0 | F5: ='Historical Data'!F5 -> 0 | G5: ='Historical Data'!G5 -> 0 | H5: ='Historical Data'!H5 -> 0 | I5: ='Historical Data'!I5 -> 0 | J5: ='Historical Data'!J5 -> 0 | ... AL5: ='Historical Data'!AL5 -> 0 | AM5: =AA5*(1+Unit2_Growth)*ScenarioMult -> 0 | AN5: =AB5*(1+Unit2_Growth)*ScenarioMult -> 0 | AO5: =AC5*(1+Unit2_Growth)*ScenarioMult -> 0 | AP5: =AD5*(1+Unit2_Growth)*ScenarioMult -> 0 | AQ5: =AE5*(1+Unit2_Growth)*ScenarioMult -> 0 | AR5: =AF5*(1+Unit2_Growth)*ScenarioMult -> 0 | AS5: =AG5*(1+Unit2_Growth)*ScenarioMult -> 0 | AT5: =AH5*(1+Unit2_Growth)*ScenarioMult -> 0 | ... BJ5: =AX5*(1+Unit2_Growth)*ScenarioMult -> 0
A6: Revenue | B6: Unit 3 | C6: ='Historical Data'!C6 -> 0 | D6: ='Historical Data'!D6 -> 0 | E6: ='Historical Data'!E6 -> 0 | F6: ='Historical Data'!F6 -> 0 | G6: ='Historical Data'!G6 -> 0 | H6: ='Historical Data'!H6 -> 0 | I6: ='Historical Data'!I6 -> 0 | J6: ='Historical Data'!J6 -> 0 | ... AL6: ='Historical Data'!AL6 -> 0 | AM6: =AA6*(1+Unit3_Growth)*ScenarioMult -> 0 | AN6: =AB6*(1+Unit3_Growth)*ScenarioMult -> 0 | AO6: =AC6*(1+Unit3_Growth)*ScenarioMult -> 0 | AP6: =AD6*(1+Unit3_Growth)*ScenarioMult -> 0 | AQ6: =AE6*(1+Unit3_Growth)*ScenarioMult -> 0 | AR6: =AF6*(1+Unit3_Growth)*ScenarioMult -> 0 | AS6: =AG6*(1+Unit3_Growth)*ScenarioMult -> 0 | AT6: =AH6*(1+Unit3_Growth)*ScenarioMult -> 0 | ... BJ6: =AX6*(1+Unit3_Growth)*ScenarioMult -> 0
A7: Revenue | B7: Unit 4 | C7: ='Historical Data'!C7 -> 0 | D7: ='Historical Data'!D7 -> 0 | E7: ='Historical Data'!E7 -> 0 | F7: ='Historical Data'!F7 -> 0 | G7: ='Historical Data'!G7 -> 0 | H7: ='Historical Data'!H7 -> 0 | I7: ='Historical Data'!I7 -> 0 | J7: ='Historical Data'!J7 -> 0 | ... AL7: ='Historical Data'!AL7 -> 0 | AM7: =AA7*(1+Unit4_Growth)*ScenarioMult -> 0 | AN7: =AB7*(1+Unit4_Growth)*ScenarioMult -> 0 | AO7: =AC7*(1+Unit4_Growth)*ScenarioMult -> 0 | AP7: =AD7*(1+Unit4_Growth)*ScenarioMult -> 0 | AQ7: =AE7*(1+Unit4_Growth)*ScenarioMult -> 0 | AR7: =AF7*(1+Unit4_Growth)*ScenarioMult -> 0 | AS7: =AG7*(1+Unit4_Growth)*ScenarioMult -> 0 | AT7: =AH7*(1+Unit4_Growth)*ScenarioMult -> 0 | ... BJ7: =AX7*(1+Unit4_Growth)*ScenarioMult -> 0
A8: Revenue | B8: Unit 5 | C8: ='Historical Data'!C8 -> 0 | D8: ='Historical Data'!D8 -> 0 | E8: ='Historical Data'!E8 -> 0 | F8: ='Historical Data'!F8 -> 0 | G8: ='Historical Data'!G8 -> 0 | H8: ='Historical Data'!H8 -> 0 | I8: ='Historical Data'!I8 -> 0 | J8: ='Historical Data'!J8 -> 0 | ... AL8: ='Historical Data'!AL8 -> 0 | AM8: =AA8*(1+Unit5_Growth)*ScenarioMult -> 0 | AN8: =AB8*(1+Unit5_Growth)*ScenarioMult -> 0 | AO8: =AC8*(1+Unit5_Growth)*ScenarioMult -> 0 | AP8: =AD8*(1+Unit5_Growth)*ScenarioMult -> 0 | AQ8: =AE8*(1+Unit5_Growth)*ScenarioMult -> 0 | AR8: =AF8*(1+Unit5_Growth)*ScenarioMult -> 0 | AS8: =AG8*(1+Unit5_Growth)*ScenarioMult -> 0 | AT8: =AH8*(1+Unit5_Growth)*ScenarioMult -> 0 | ... BJ8: =AX8*(1+Unit5_Growth)*ScenarioMult -> 0
A9: Consolidated Revenue | C9: =SUM(C4:C8) -> 0 | D9: =SUM(D4:D8) -> 0 | E9: =SUM(E4:E8) -> 0 | F9: =SUM(F4:F8) -> 0 | G9: =SUM(G4:G8) -> 0 | H9: =SUM(H4:H8) -> 0 | I9: =SUM(I4:I8) -> 0 | J9: =SUM(J4:J8) -> 0 | ... BJ9: =SUM(BJ4:BJ8) -> 0

Sheet COGS & Gross Margin
A1: Cost of Goods Sold & Gross Margin
C2: 44197 | D2: 44228 | E2: 44256 | F2: 44287 | G2: 44317 | H2: 44348 | I2: 44378 | J2: 44409 | K2: 44440 | L2: 44470 | M2: 44501 | N2: 44531 | O2: 44562 | P2: 44593 | Q2: 44621 | R2: 44652 | S2: 44682 | T2: 44713 | U2: 44743 | V2: 44774 | W2: 44805 | X2: 44835 | Y2: 44866 | Z2: 44896 | AA2: 44927 | AB2: 44958 | AC2: 44986 | AD2: 45017 | AE2: 45047 | AF2: 45078 | AG2: 45108 | AH2: 45139 | AI2: 45170 | AJ2: 45200 | AK2: 45231 | AL2: 45261 | AM2: 45292 | AN2: 45323 | AO2: 45352 | AP2: 45383 | AQ2: 45413 | AR2: 45444 | AS2: 45474 | AT2: 45505 | AU2: 45536 | AV2: 45566 | AW2: 45597 | AX2: 45627 | AY2: 45658 | AZ2: 45689 | BA2: 45717 | BB2: 45748 | BC2: 45778 | BD2: 45809 | BE2: 45839 | BF2: 45870 | BG2: 45901 | BH2: 45931 | BI2: 45962 | BJ2: 45992
A3: Category | B3: Unit | C3: Actual | D3: Actual | E3: Actual | F3: Actual | G3: Actual | H3: Actual | I3: Actual | J3: Actual | K3: Actual | L3: Actual | M3: Actual | N3: Actual | O3: Actual | P3: Actual | Q3: Actual | R3: Actual | S3: Actual | T3: Actual | U3: Actual | V3: Actual | W3: Actual | X3: Actual | Y3: Actual | Z3: Actual | AA3: Actual | AB3: Actual | AC3: Actual | AD3: Actual | AE3: Actual | AF3: Actual | AG3: Actual | AH3: Actual | AI3: Actual | AJ3: Actual | AK3: Actual | AL3: Actual | AM3: Forecast | AN3: Forecast | AO3: Forecast | AP3: Forecast | AQ3: Forecast | AR3: Forecast | AS3: Forecast | AT3: Forecast | AU3: Forecast | AV3: Forecast | AW3: Forecast | AX3: Forecast | AY3: Forecast | AZ3: Forecast | BA3: Forecast | BB3: Forecast | BC3: Forecast | BD3: Forecast | BE3: Forecast | BF3: Forecast | BG3: Forecast | BH3: Forecast | BI3: Forecast | BJ3: Forecast
A4: COGS | B4: Unit 1 | C4: ='Historical Data'!C5 -> 0 | D4: ='Historical Data'!D5 -> 0 | E4: ='Historical Data'!E5 -> 0 | F4: ='Historical Data'!F5 -> 0 | G4: ='Historical Data'!G5 -> 0 | H4: ='Historical Data'!H5 -> 0 | I4: ='Historical Data'!I5 -> 0 | J4: ='Historical Data'!J5 -> 0 | ... AL4: ='Historical Data'!AL5 -> 0 | AM4: ='Revenue Forecast'!AM4*Driver_COGS -> 0 | AN4: ='Revenue Forecast'!AN4*Driver_COGS -> 0 | AO4: ='Revenue Forecast'!AO4*Driver_COGS -> 0 | AP4: ='Revenue Forecast'!AP4*Driver_COGS -> 0 | AQ4: ='Revenue Forecast'!AQ4*Driver_COGS -> 0 | AR4: ='Revenue Forecast'!AR4*Driver_COGS -> 0 | AS4: ='Revenue Forecast'!AS4*Driver_COGS -> 0 | AT4: ='Revenue Forecast'!AT4*Driver_COGS -> 0 | ... BJ4: ='Revenue Forecast'!BJ4*Driver_COGS -> 0
A5: COGS | B5: Unit 2 | C5: ='Historical Data'!C13 -> 0 | D5: ='Historical Data'!D13 -> 0 | E5: ='Historical Data'!E13 -> 0 | F5: ='Historical Data'!F13 -> 0 | G5: ='Historical Data'!G13 -> 0 | H5: ='Historical Data'!H13 -> 0 | I5: ='Historical Data'!I13 -> 0 | J5: ='Historical Data'!J13 -> 0 | ... AL5: ='Historical Data'!AL13 -> 0 | AM5: ='Revenue Forecast'!AM5*Driver_COGS -> 0 | AN5: ='Revenue Forecast'!AN5*Driver_COGS -> 0 | AO5: ='Revenue Forecast'!AO5*Driver_COGS -> 0 | AP5: ='Revenue Forecast'!AP5*Driver_COGS -> 0 | AQ5: ='Revenue Forecast'!AQ5*Driver_COGS -> 0 | AR5: ='Revenue Forecast'!AR5*Driver_COGS -> 0 | AS5: ='Revenue Forecast'!AS5*Driver_COGS -> 0 | AT5: ='Revenue Forecast'!AT5*Driver_COGS -> 0 | ... BJ5: ='Revenue Forecast'!BJ5*Driver_COGS -> 0
A6: COGS | B6: Unit 3 | C6: ='Historical Data'!C21 -> 0 | D6: ='Historical Data'!D21 -> 0 | E6: ='Historical Data'!E21 -> 0 | F6: ='Historical Data'!F21 -> 0 | G6: ='Historical Data'!G21 -> 0 | H6: ='Historical Data'!H21 -> 0 | I6: ='Historical Data'!I21 -> 0 | J6: ='Historical Data'!J21 -> 0 | ... AL6: ='Historical Data'!AL21 -> 0 | AM6: ='Revenue Forecast'!AM6*Driver_COGS -> 0 | AN6: ='Revenue Forecast'!AN6*Driver_COGS -> 0 | AO6: ='Revenue Forecast'!AO6*Driver_COGS -> 0 | AP6: ='Revenue Forecast'!AP6*Driver_COGS -> 0 | AQ6: ='Revenue Forecast'!AQ6*Driver_COGS -> 0 | AR6: ='Revenue Forecast'!AR6*Driver_COGS -> 0 | AS6: ='Revenue Forecast'!AS6*Driver_COGS -> 0 | AT6: ='Revenue Forecast'!AT6*Driver_COGS -> 0 | ... BJ6: ='Revenue Forecast'!BJ6*Driver_COGS -> 0
A7: COGS | B7: Unit 4 | C7: ='Historical Data'!C29 -> 0 | D7: ='Historical Data'!D29 -> 0 | E7: ='Historical Data'!E29 -> 0 | F7: ='Historical Data'!F29 -> 0 | G7: ='Historical Data'!G29 -> 0 | H7: ='Historical Data'!H29 -> 0 | I7: ='Historical Data'!I29 -> 0 | J7: ='Historical Data'!J29 -> 0 | ... AL7: ='Historical Data'!AL29 -> 0 | AM7: ='Revenue Forecast'!AM7*Driver_COGS -> 0 | AN7: ='Revenue Forecast'!AN7*Driver_COGS -> 0 | AO7: ='Revenue Forecast'!AO7*Driver_COGS -> 0 | AP7: ='Revenue Forecast'!AP7*Driver_COGS -> 0 | AQ7: ='Revenue Forecast'!AQ7*Driver_COGS -> 0 | AR7: ='Revenue Forecast'!AR7*Driver_COGS -> 0 | AS7: ='Revenue Forecast'!AS7*Driver_COGS -> 0 | AT7: ='Revenue Forecast'!AT7*Driver_COGS -> 0 | ... BJ7: ='Revenue Forecast'!BJ7*Driver_COGS -> 0
A8: COGS | B8: Unit 5 | C8: ='Historical Data'!C37 -> 0 | D8: ='Historical Data'!D37 -> 0 | E8: ='Historical Data'!E37 -> 0 | F8: ='Historical Data'!F37 -> 0 | G8: ='Historical Data'!G37 -> 0 | H8: ='Historical Data'!H37 -> 0 | I8: ='Historical Data'!I37 -> 0 | J8: ='Historical Data'!J37 -> 0 | ... AL8: ='Historical Data'!AL37 -> 0 | AM8: ='Revenue Forecast'!AM8*Driver_COGS -> 0 | AN8: ='Revenue Forecast'!AN8*Driver_COGS -> 0 | AO8: ='Revenue Forecast'!AO8*Driver_COGS -> 0 | AP8: ='Revenue Forecast'!AP8*Driver_COGS -> 0 | AQ8: ='Revenue Forecast'!AQ8*Driver_COGS -> 0 | AR8: ='Revenue Forecast'!AR8*Driver_COGS -> 0 | AS8: ='Revenue Forecast'!AS8*Driver_COGS -> 0 | AT8: ='Revenue Forecast'!AT8*Driver_COGS -> 0 | ... BJ8: ='Revenue Forecast'!BJ8*Driver_COGS -> 0
A9: Consolidated COGS | C9: =SUM(C4:C8) -> 0 | D9: =SUM(D4:D8) -> 0 | E9: =SUM(E4:E8) -> 0 | F9: =SUM(F4:F8) -> 0 | G9: =SUM(G4:G8) -> 0 | H9: =SUM(H4:H8) -> 0 | I9: =SUM(I4:I8) -> 0 | J9: =SUM(J4:J8) -> 0 | ... BJ9: =SUM(BJ4:BJ8) -> 0
A11: Gross Margin $ | C11: ='Revenue Forecast'!C9-C9 -> 0 | D11: ='Revenue Forecast'!D9-D9 -> 0 | E11: ='Revenue Forecast'!E9-E9 -> 0 | F11: ='Revenue Forecast'!F9-F9 -> 0 | G11: ='Revenue Forecast'!G9-G9 -> 0 | H11: ='Revenue Forecast'!H9-H9 -> 0 | I11: ='Revenue Forecast'!I9-I9 -> 0 | J11: ='Revenue Forecast'!J9-J9 -> 0 | ... BJ11: ='Revenue Forecast'!BJ9-BJ9 -> 0
A12: Gross Margin % | C12: =IFERROR(C11/'Revenue Forecast'!C9, 0) -> 0 | D12: =IFERROR(D11/'Revenue Forecast'!D9, 0) -> 0 | E12: =IFERROR(E11/'Revenue Forecast'!E9, 0) -> 0 | F12: =IFERROR(F11/'Revenue Forecast'!F9, 0) -> 0 | G12: =IFERROR(G11/'Revenue Forecast'!G9, 0) -> 0 | H12: =IFERROR(H11/'Revenue Forecast'!H9, 0) -> 0 | I12: =IFERROR(I11/'Revenue Forecast'!I9, 0) -> 0 | J12: =IFERROR(J11/'Revenue Forecast'!J9, 0) -> 0 | ... BJ12: =IFERROR(BJ11/'Revenue Forecast'!BJ9, 0) -> 0

Sheet OpEx
A1: Operating Expenses
C2: 44197 | D2: 44228 | E2: 44256 | F2: 44287 | G2: 44317 | H2: 44348 | I2: 44378 | J2: 44409 | K2: 44440 | L2: 44470 | M2: 44501 | N2: 44531 | O2: 44562 | P2: 44593 | Q2: 44621 | R2: 44652 | S2: 44682 | T2: 44713 | U2: 44743 | V2: 44774 | W2: 44805 | X2: 44835 | Y2: 44866 | Z2: 44896 | AA2: 44927 | AB2: 44958 | AC2: 44986 | AD2: 45017 | AE2: 45047 | AF2: 45078 | AG2: 45108 | AH2: 45139 | AI2: 45170 | AJ2: 45200 | AK2: 45231 | AL2: 45261 | AM2: 45292 | AN2: 45323 | AO2: 45352 | AP2: 45383 | AQ2: 45413 | AR2: 45444 | AS2: 45474 | AT2: 45505 | AU2: 45536 | AV2: 45566 | AW2: 45597 | AX2: 45627 | AY2: 45658 | AZ2: 45689 | BA2: 45717 | BB2: 45748 | BC2: 45778 | BD2: 45809 | BE2: 45839 | BF2: 45870 | BG2: 45901 | BH2: 45931 | BI2: 45962 | BJ2: 45992
A3: Category | B3: Unit | C3: Actual | D3: Actual | E3: Actual | F3: Actual | G3: Actual | H3: Actual | I3: Actual | J3: Actual | K3: Actual | L3: Actual | M3: Actual | N3: Actual | O3: Actual | P3: Actual | Q3: Actual | R3: Actual | S3: Actual | T3: Actual | U3: Actual | V3: Actual | W3: Actual | X3: Actual | Y3: Actual | Z3: Actual | AA3: Actual | AB3: Actual | AC3: Actual | AD3: Actual | AE3: Actual | AF3: Actual | AG3: Actual | AH3: Actual | AI3: Actual | AJ3: Actual | AK3: Actual | AL3: Actual | AM3: Forecast | AN3: Forecast | AO3: Forecast | AP3: Forecast | AQ3: Forecast | AR3: Forecast | AS3: Forecast | AT3: Forecast | AU3: Forecast | AV3: Forecast | AW3: Forecast | AX3: Forecast | AY3: Forecast | AZ3: Forecast | BA3: Forecast | BB3: Forecast | BC3: Forecast | BD3: Forecast | BE3: Forecast | BF3: Forecast | BG3: Forecast | BH3: Forecast | BI3: Forecast | BJ3: Forecast
A4: Payroll
A5: Payroll | B5: Unit 1 | C5: ='Historical Data'!C6 -> 0 | D5: ='Historical Data'!D6 -> 0 | E5: ='Historical Data'!E6 -> 0 | F5: ='Historical Data'!F6 -> 0 | G5: ='Historical Data'!G6 -> 0 | H5: ='Historical Data'!H6 -> 0 | I5: ='Historical Data'!I6 -> 0 | J5: ='Historical Data'!J6 -> 0 | ... AL5: ='Historical Data'!AL6 -> 0 | AM5: ='Revenue Forecast'!AM4*Driver_Payroll -> 0 | AN5: ='Revenue Forecast'!AN4*Driver_Payroll -> 0 | AO5: ='Revenue Forecast'!AO4*Driver_Payroll -> 0 | AP5: ='Revenue Forecast'!AP4*Driver_Payroll -> 0 | AQ5: ='Revenue Forecast'!AQ4*Driver_Payroll -> 0 | AR5: ='Revenue Forecast'!AR4*Driver_Payroll -> 0 | AS5: ='Revenue Forecast'!AS4*Driver_Payroll -> 0 | AT5: ='Revenue Forecast'!AT4*Driver_Payroll -> 0 | ... BJ5: ='Revenue Forecast'!BJ4*Driver_Payroll -> 0
A6: Payroll | B6: Unit 2 | C6: ='Historical Data'!C14 -> 0 | D6: ='Historical Data'!D14 -> 0 | E6: ='Historical Data'!E14 -> 0 | F6: ='Historical Data'!F14 -> 0 | G6: ='Historical Data'!G14 -> 0 | H6: ='Historical Data'!H14 -> 0 | I6: ='Historical Data'!I14 -> 0 | J6: ='Historical Data'!J14 -> 0 | ... AL6: ='Historical Data'!AL14 -> 0 | AM6: ='Revenue Forecast'!AM5*Driver_Payroll -> 0 | AN6: ='Revenue Forecast'!AN5*Driver_Payroll -> 0 | AO6: ='Revenue Forecast'!AO5*Driver_Payroll -> 0 | AP6: ='Revenue Forecast'!AP5*Driver_Payroll -> 0 | AQ6: ='Revenue Forecast'!AQ5*Driver_Payroll -> 0 | AR6: ='Revenue Forecast'!AR5*Driver_Payroll -> 0 | AS6: ='Revenue Forecast'!AS5*Driver_Payroll -> 0 | AT6: ='Revenue Forecast'!AT5*Driver_Payroll -> 0 | ... BJ6: ='Revenue Forecast'!BJ5*Driver_Payroll -> 0
A7: Payroll | B7: Unit 3 | C7: ='Historical Data'!C22 -> 0 | D7: ='Historical Data'!D22 -> 0 | E7: ='Historical Data'!E22 -> 0 | F7: ='Historical Data'!F22 -> 0 | G7: ='Historical Data'!G22 -> 0 | H7: ='Historical Data'!H22 -> 0 | I7: ='Historical Data'!I22 -> 0 | J7: ='Historical Data'!J22 -> 0 | ... AL7: ='Historical Data'!AL22 -> 0 | AM7: ='Revenue Forecast'!AM6*Driver_Payroll -> 0 | AN7: ='Revenue Forecast'!AN6*Driver_Payroll -> 0 | AO7: ='Revenue Forecast'!AO6*Driver_Payroll -> 0 | AP7: ='Revenue Forecast'!AP6*Driver_Payroll -> 0 | AQ7: ='Revenue Forecast'!AQ6*Driver_Payroll -> 0 | AR7: ='Revenue Forecast'!AR6*Driver_Payroll -> 0 | AS7: ='Revenue Forecast'!AS6*Driver_Payroll -> 0 | AT7: ='Revenue Forecast'!AT6*Driver_Payroll -> 0 | ... BJ7: ='Revenue Forecast'!BJ6*Driver_Payroll -> 0
A8: Payroll | B8: Unit 4 | C8: ='Historical Data'!C30 -> 0 | D8: ='Historical Data'!D30 -> 0 | E8: ='Historical Data'!E30 -> 0 | F8: ='Historical Data'!F30 -> 0 | G8: ='Historical Data'!G30 -> 0 | H8: ='Historical Data'!H30 -> 0 | I8: ='Historical Data'!I30 -> 0 | J8: ='Historical Data'!J30 -> 0 | ... AL8: ='Historical Data'!AL30 -> 0 | AM8: ='Revenue Forecast'!AM7*Driver_Payroll -> 0 | AN8: ='Revenue Forecast'!AN7*Driver_Payroll -> 0 | AO8: ='Revenue Forecast'!AO7*Driver_Payroll -> 0 | AP8: ='Revenue Forecast'!AP7*Driver_Payroll -> 0 | AQ8: ='Revenue Forecast'!AQ7*Driver_Payroll -> 0 | AR8: ='Revenue Forecast'!AR7*Driver_Payroll -> 0 | AS8: ='Revenue Forecast'!AS7*Driver_Payroll -> 0 | AT8: ='Revenue Forecast'!AT7*Driver_Payroll -> 0 | ... BJ8: ='Revenue Forecast'!BJ7*Driver_Payroll -> 0
A9: Payroll | B9: Unit 5 | C9: ='Historical Data'!C38 -> 0 | D9: ='Historical Data'!D38 -> 0 | E9: ='Historical Data'!E38 -> 0 | F9: ='Historical Data'!F38 -> 0 | G9: ='Historical Data'!G38 -> 0 | H9: ='Historical Data'!H38 -> 0 | I9: ='Historical Data'!I38 -> 0 | J9: ='Historical Data'!J38 -> 0 | ... AL9: ='Historical Data'!AL38 -> 0 | AM9: ='Revenue Forecast'!AM8*Driver_Payroll -> 0 | AN9: ='Revenue Forecast'!AN8*Driver_Payroll -> 0 | AO9: ='Revenue Forecast'!AO8*Driver_Payroll -> 0 | AP9: ='Revenue Forecast'!AP8*Driver_Payroll -> 0 | AQ9: ='Revenue Forecast'!AQ8*Driver_Payroll -> 0 | AR9: ='Revenue Forecast'!AR8*Driver_Payroll -> 0 | AS9: ='Revenue Forecast'!AS8*Driver_Payroll -> 0 | AT9: ='Revenue Forecast'!AT8*Driver_Payroll -> 0 | ... BJ9: ='Revenue Forecast'!BJ8*Driver_Payroll -> 0
A10: Total Payroll | C10: =SUM(C5:C9) -> 0 | D10: =SUM(D5:D9) -> 0 | E10: =SUM(E5:E9) -> 0 | F10: =SUM(F5:F9) -> 0 | G10: =SUM(G5:G9) -> 0 | H10: =SUM(H5:H9) -> 0 | I10: =SUM(I5:I9) -> 0 | J10: =SUM(J5:J9) -> 0 | ... BJ10: =SUM(BJ5:BJ9) -> 0
A12: Rent
A13: Rent | B13: Unit 1 | C13: ='Historical Data'!C7 -> 0 | D13: ='Historical Data'!D7 -> 0 | E13: ='Historical Data'!E7 -> 0 | F13: ='Historical Data'!F7 -> 0 | G13: ='Historical Data'!G7 -> 0 | H13: ='Historical Data'!H7 -> 0 | I13: ='Historical Data'!I7 -> 0 | J13: ='Historical Data'!J7 -> 0 | ... AL13: ='Historical Data'!AL7 -> 0 | AM13: =AA13*(1+Rent_Escalation) -> 0 | AN13: =AB13*(1+Rent_Escalation) -> 0 | AO13: =AC13*(1+Rent_Escalation) -> 0 | AP13: =AD13*(1+Rent_Escalation) -> 0 | AQ13: =AE13*(1+Rent_Escalation) -> 0 | AR13: =AF13*(1+Rent_Escalation) -> 0 | AS13: =AG13*(1+Rent_Escalation) -> 0 | AT13: =AH13*(1+Rent_Escalation) -> 0 | ... BJ13: =AX13*(1+Rent_Escalation) -> 0
A14: Rent | B14: Unit 2 | C14: ='Historical Data'!C15 -> 0 | D14: ='Historical Data'!D15 -> 0 | E14: ='Historical Data'!E15 -> 0 | F14: ='Historical Data'!F15 -> 0 | G14: ='Historical Data'!G15 -> 0 | H14: ='Historical Data'!H15 -> 0 | I14: ='Historical Data'!I15 -> 0 | J14: ='Historical Data'!J15 -> 0 | ... AL14: ='Historical Data'!AL15 -> 0 | AM14: =AA14*(1+Rent_Escalation) -> 0 | AN14: =AB14*(1+Rent_Escalation) -> 0 | AO14: =AC14*(1+Rent_Escalation) -> 0 | AP14: =AD14*(1+Rent_Escalation) -> 0 | AQ14: =AE14*(1+Rent_Escalation) -> 0 | AR14: =AF14*(1+Rent_Escalation) -> 0 | AS14: =AG14*(1+Rent_Escalation) -> 0 | AT14: =AH14*(1+Rent_Escalation) -> 0 | ... BJ14: =AX14*(1+Rent_Escalation) -> 0
A15: Rent | B15: Unit 3 | C15: ='Historical Data'!C23 -> 0 | D15: ='Historical Data'!D23 -> 0 | E15: ='Historical Data'!E23 -> 0 | F15: ='Historical Data'!F23 -> 0 | G15: ='Historical Data'!G23 -> 0 | H15: ='Historical Data'!H23 -> 0 | I15: ='Historical Data'!I23 -> 0 | J15: ='Historical Data'!J23 -> 0 | ... AL15: ='Historical Data'!AL23 -> 0 | AM15: =AA15*(1+Rent_Escalation) -> 0 | AN15: =AB15*(1+Rent_Escalation) -> 0 | AO15: =AC15*(1+Rent_Escalation) -> 0 | AP15: =AD15*(1+Rent_Escalation) -> 0 | AQ15: =AE15*(1+Rent_Escalation) -> 0 | AR15: =AF15*(1+Rent_Escalation) -> 0 | AS15: =AG15*(1+Rent_Escalation) -> 0 | AT15: =AH15*(1+Rent_Escalation) -> 0 | ... BJ15: =AX15*(1+Rent_Escalation) -> 0
A16: Rent | B16: Unit 4 | C16: ='Historical Data'!C31 -> 0 | D16: ='Historical Data'!D31 -> 0 | E16: ='Historical Data'!E31 -> 0 | F16: ='Historical Data'!F31 -> 0 | G16: ='Historical Data'!G31 -> 0 | H16: ='Historical Data'!H31 -> 0 | I16: ='Historical Data'!I31 -> 0 | J16: ='Historical Data'!J31 -> 0 | ... AL16: ='Historical Data'!AL31 -> 0 | AM16: =AA16*(1+Rent_Escalation) -> 0 | AN16: =AB16*(1+Rent_Escalation) -> 0 | AO16: =AC16*(1+Rent_Escalation) -> 0 | AP16: =AD16*(1+Rent_Escalation) -> 0 | AQ16: =AE16*(1+Rent_Escalation) -> 0 | AR16: =AF16*(1+Rent_Escalation) -> 0 | AS16: =AG16*(1+Rent_Escalation) -> 0 | AT16: =AH16*(1+Rent_Escalation) -> 0 | ... BJ16: =AX16*(1+Rent_Escalation) -> 0
A17: Rent | B17: Unit 5 | C17: ='Historical Data'!C39 -> 0 | D17: ='Historical Data'!D39 -> 0 | E17: ='Historical Data'!E39 -> 0 | F17: ='Historical Data'!F39 -> 0 | G17: ='Historical Data'!G39 -> 0 | H17: ='Historical Data'!H39 -> 0 | I17: ='Historical Data'!I39 -> 0 | J17: ='Historical Data'!J39 -> 0 | ... AL17: ='Historical Data'!AL39 -> 0 | AM17: =AA17*(1+Rent_Escalation) -> 0 | AN17: =AB17*(1+Rent_Escalation) -> 0 | AO17: =AC17*(1+Rent_Escalation) -> 0 | AP17: =AD17*(1+Rent_Escalation) -> 0 | AQ17: =AE17*(1+Rent_Escalation) -> 0 | AR17: =AF17*(1+Rent_Escalation) -> 0 | AS17: =AG17*(1+Rent_Escalation) -> 0 | AT17: =AH17*(1+Rent_Escalation) -> 0 | ... BJ17: =AX17*(1+Rent_Escalation) -> 0
A18: Total Rent | C18: =SUM(C13:C17) -> 0 | D18: =SUM(D13:D17) -> 0 | E18: =SUM(E13:E17) -> 0 | F18: =SUM(F13:F17) -> 0 | G18: =SUM(G13:G17) -> 0 | H18: =SUM(H13:H17) -> 0 | I18: =SUM(I13:I17) -> 0 | J18: =SUM(J13:J17) -> 0 | ... BJ18: =SUM(BJ13:BJ17) -> 0
A20: Marketing
A21: Marketing | B21: Unit 1 | C21: ='Historical Data'!C8 -> 0 | D21: ='Historical Data'!D8 -> 0 | E21: ='Historical Data'!E8 -> 0 | F21: ='Historical Data'!F8 -> 0 | G21: ='Historical Data'!G8 -> 0 | H21: ='Historical Data'!H8 -> 0 | I21: ='Historical Data'!I8 -> 0 | J21: ='Historical Data'!J8 -> 0 | ... AL21: ='Historical Data'!AL8 -> 0 | AM21: ='Revenue Forecast'!AM4*Driver_Marketing -> 0 | AN21: ='Revenue Forecast'!AN4*Driver_Marketing -> 0 | AO21: ='Revenue Forecast'!AO4*Driver_Marketing -> 0 | AP21: ='Revenue Forecast'!AP4*Driver_Marketing -> 0 | AQ21: ='Revenue Forecast'!AQ4*Driver_Marketing -> 0 | AR21: ='Revenue Forecast'!AR4*Driver_Marketing -> 0 | AS21: ='Revenue Forecast'!AS4*Driver_Marketing -> 0 | AT21: ='Revenue Forecast'!AT4*Driver_Marketing -> 0 | ... BJ21: ='Revenue Forecast'!BJ4*Driver_Marketing -> 0
A22: Marketing | B22: Unit 2 | C22: ='Historical Data'!C16 -> 0 | D22: ='Historical Data'!D16 -> 0 | E22: ='Historical Data'!E16 -> 0 | F22: ='Historical Data'!F16 -> 0 | G22: ='Historical Data'!G16 -> 0 | H22: ='Historical Data'!H16 -> 0 | I22: ='Historical Data'!I16 -> 0 | J22: ='Historical Data'!J16 -> 0 | ... AL22: ='Historical Data'!AL16 -> 0 | AM22: ='Revenue Forecast'!AM5*Driver_Marketing -> 0 | AN22: ='Revenue Forecast'!AN5*Driver_Marketing -> 0 | AO22: ='Revenue Forecast'!AO5*Driver_Marketing -> 0 | AP22: ='Revenue Forecast'!AP5*Driver_Marketing -> 0 | AQ22: ='Revenue Forecast'!AQ5*Driver_Marketing -> 0 | AR22: ='Revenue Forecast'!AR5*Driver_Marketing -> 0 | AS22: ='Revenue Forecast'!AS5*Driver_Marketing -> 0 | AT22: ='Revenue Forecast'!AT5*Driver_Marketing -> 0 | ... BJ22: ='Revenue Forecast'!BJ5*Driver_Marketing -> 0
A23: Marketing | B23: Unit 3 | C23: ='Historical Data'!C24 -> 0 | D23: ='Historical Data'!D24 -> 0 | E23: ='Historical Data'!E24 -> 0 | F23: ='Historical Data'!F24 -> 0 | G23: ='Historical Data'!G24 -> 0 | H23: ='Historical Data'!H24 -> 0 | I23: ='Historical Data'!I24 -> 0 | J23: ='Historical Data'!J24 -> 0 | ... AL23: ='Historical Data'!AL24 -> 0 | AM23: ='Revenue Forecast'!AM6*Driver_Marketing -> 0 | AN23: ='Revenue Forecast'!AN6*Driver_Marketing -> 0 | AO23: ='Revenue Forecast'!AO6*Driver_Marketing -> 0 | AP23: ='Revenue Forecast'!AP6*Driver_Marketing -> 0 | AQ23: ='Revenue Forecast'!AQ6*Driver_Marketing -> 0 | AR23: ='Revenue Forecast'!AR6*Driver_Marketing -> 0 | AS23: ='Revenue Forecast'!AS6*Driver_Marketing -> 0 | AT23: ='Revenue Forecast'!AT6*Driver_Marketing -> 0 | ... BJ23: ='Revenue Forecast'!BJ6*Driver_Marketing -> 0
A24: Marketing | B24: Unit 4 | C24: ='Historical Data'!C32 -> 0 | D24: ='Historical Data'!D32 -> 0 | E24: ='Historical Data'!E32 -> 0 | F24: ='Historical Data'!F32 -> 0 | G24: ='Historical Data'!G32 -> 0 | H24: ='Historical Data'!H32 -> 0 | I24: ='Historical Data'!I32 -> 0 | J24: ='Historical Data'!J32 -> 0 | ... AL24: ='Historical Data'!AL32 -> 0 | AM24: ='Revenue Forecast'!AM7*Driver_Marketing -> 0 | AN24: ='Revenue Forecast'!AN7*Driver_Marketing -> 0 | AO24: ='Revenue Forecast'!AO7*Driver_Marketing -> 0 | AP24: ='Revenue Forecast'!AP7*Driver_Marketing -> 0 | AQ24: ='Revenue Forecast'!AQ7*Driver_Marketing -> 0 | AR24: ='Revenue Forecast'!AR7*Driver_Marketing -> 0 | AS24: ='Revenue Forecast'!AS7*Driver_Marketing -> 0 | AT24: ='Revenue Forecast'!AT7*Driver_Marketing -> 0 | ... BJ24: ='Revenue Forecast'!BJ7*Driver_Marketing -> 0
A25: Marketing | B25: Unit 5 | C25: ='Historical Data'!C40 -> 0 | D25: ='Historical Data'!D40 -> 0 | E25: ='Historical Data'!E40 -> 0 | F25: ='Historical Data'!F40 -> 0 | G25: ='Historical Data'!G40 -> 0 | H25: ='Historical Data'!H40 -> 0 | I25: ='Historical Data'!I40 -> 0 | J25: ='Historical Data'!J40 -> 0 | ... AL25: ='Historical Data'!AL40 -> 0 | AM25: ='Revenue Forecast'!AM8*Driver_Marketing -> 0 | AN25: ='Revenue Forecast'!AN8*Driver_Marketing -> 0 | AO25: ='Revenue Forecast'!AO8*Driver_Marketing -> 0 | AP25: ='Revenue Forecast'!AP8*Driver_Marketing -> 0 | AQ25: ='Revenue Forecast'!AQ8*Driver_Marketing -> 0 | AR25: ='Revenue Forecast'!AR8*Driver_Marketing -> 0 | AS25: ='Revenue Forecast'!AS8*Driver_Marketing -> 0 | AT25: ='Revenue Forecast'!AT8*Driver_Marketing -> 0 | ... BJ25: ='Revenue Forecast'!BJ8*Driver_Marketing -> 0
A26: Total Marketing | C26: =SUM(C21:C25) -> 0 | D26: =SUM(D21:D25) -> 0 | E26: =SUM(E21:E25) -> 0 | F26: =SUM(F21:F25) -> 0 | G26: =SUM(G21:G25) -> 0 | H26: =SUM(H21:H25) -> 0 | I26: =SUM(I21:I25) -> 0 | J26: =SUM(J21:J25) -> 0 | ... BJ26: =SUM(BJ21:BJ25) -> 0
A28: Utilities
A29: Utilities | B29: Unit 1 | C29: ='Historical Data'!C9 -> 0 | D29: ='Historical Data'!D9 -> 0 | E29: ='Historical Data'!E9 -> 0 | F29: ='Historical Data'!F9 -> 0 | G29: ='Historical Data'!G9 -> 0 | H29: ='Historical Data'!H9 -> 0 | I29: ='Historical Data'!I9 -> 0 | J29: ='Historical Data'!J9 -> 0 | ... AL29: ='Historical Data'!AL9 -> 0 | AM29: ='Revenue Forecast'!AM4*Driver_Utilities -> 0 | AN29: ='Revenue Forecast'!AN4*Driver_Utilities -> 0 | AO29: ='Revenue Forecast'!AO4*Driver_Utilities -> 0 | AP29: ='Revenue Forecast'!AP4*Driver_Utilities -> 0 | AQ29: ='Revenue Forecast'!AQ4*Driver_Utilities -> 0 | AR29: ='Revenue Forecast'!AR4*Driver_Utilities -> 0 | AS29: ='Revenue Forecast'!AS4*Driver_Utilities -> 0 | AT29: ='Revenue Forecast'!AT4*Driver_Utilities -> 0 | ... BJ29: ='Revenue Forecast'!BJ4*Driver_Utilities -> 0
A30: Utilities | B30: Unit 2 | C30: ='Historical Data'!C17 -> 0 | D30: ='Historical Data'!D17 -> 0 | E30: ='Historical Data'!E17 -> 0 | F30: ='Historical Data'!F17 -> 0 | G30: ='Historical Data'!G17 -> 0 | H30: ='Historical Data'!H17 -> 0 | I30: ='Historical Data'!I17 -> 0 | J30: ='Historical Data'!J17 -> 0 | ... AL30: ='Historical Data'!AL17 -> 0 | AM30: ='Revenue Forecast'!AM5*Driver_Utilities -> 0 | AN30: ='Revenue Forecast'!AN5*Driver_Utilities -> 0 | AO30: ='Revenue Forecast'!AO5*Driver_Utilities -> 0 | AP30: ='Revenue Forecast'!AP5*Driver_Utilities -> 0 | AQ30: ='Revenue Forecast'!AQ5*Driver_Utilities -> 0 | AR30: ='Revenue Forecast'!AR5*Driver_Utilities -> 0 | AS30: ='Revenue Forecast'!AS5*Driver_Utilities -> 0 | AT30: ='Revenue Forecast'!AT5*Driver_Utilities -> 0 | ... BJ30: ='Revenue Forecast'!BJ5*Driver_Utilities -> 0
A31: Utilities | B31: Unit 3 | C31: ='Historical Data'!C25 -> 0 | D31: ='Historical Data'!D25 -> 0 | E31: ='Historical Data'!E25 -> 0 | F31: ='Historical Data'!F25 -> 0 | G31: ='Historical Data'!G25 -> 0 | H31: ='Historical Data'!H25 -> 0 | I31: ='Historical Data'!I25 -> 0 | J31: ='Historical Data'!J25 -> 0 | ... AL31: ='Historical Data'!AL25 -> 0 | AM31: ='Revenue Forecast'!AM6*Driver_Utilities -> 0 | AN31: ='Revenue Forecast'!AN6*Driver_Utilities -> 0 | AO31: ='Revenue Forecast'!AO6*Driver_Utilities -> 0 | AP31: ='Revenue Forecast'!AP6*Driver_Utilities -> 0 | AQ31: ='Revenue Forecast'!AQ6*Driver_Utilities -> 0 | AR31: ='Revenue Forecast'!AR6*Driver_Utilities -> 0 | AS31: ='Revenue Forecast'!AS6*Driver_Utilities -> 0 | AT31: ='Revenue Forecast'!AT6*Driver_Utilities -> 0 | ... BJ31: ='Revenue Forecast'!BJ6*Driver_Utilities -> 0
A32: Utilities | B32: Unit 4 | C32: ='Historical Data'!C33 -> 0 | D32: ='Historical Data'!D33 -> 0 | E32: ='Historical Data'!E33 -> 0 | F32: ='Historical Data'!F33 -> 0 | G32: ='Historical Data'!G33 -> 0 | H32: ='Historical Data'!H33 -> 0 | I32: ='Historical Data'!I33 -> 0 | J32: ='Historical Data'!J33 -> 0 | ... AL32: ='Historical Data'!AL33 -> 0 | AM32: ='Revenue Forecast'!AM7*Driver_Utilities -> 0 | AN32: ='Revenue Forecast'!AN7*Driver_Utilities -> 0 | AO32: ='Revenue Forecast'!AO7*Driver_Utilities -> 0 | AP32: ='Revenue Forecast'!AP7*Driver_Utilities -> 0 | AQ32: ='Revenue Forecast'!AQ7*Driver_Utilities -> 0 | AR32: ='Revenue Forecast'!AR7*Driver_Utilities -> 0 | AS32: ='Revenue Forecast'!AS7*Driver_Utilities -> 0 | AT32: ='Revenue Forecast'!AT7*Driver_Utilities -> 0 | ... BJ32: ='Revenue Forecast'!BJ7*Driver_Utilities -> 0
A33: Utilities | B33: Unit 5 | C33: ='Historical Data'!C41 -> 0 | D33: ='Historical Data'!D41 -> 0 | E33: ='Historical Data'!E41 -> 0 | F33: ='Historical Data'!F41 -> 0 | G33: ='Historical Data'!G41 -> 0 | H33: ='Historical Data'!H41 -> 0 | I33: ='Historical Data'!I41 -> 0 | J33: ='Historical Data'!J41 -> 0 | ... AL33: ='Historical Data'!AL41 -> 0 | AM33: ='Revenue Forecast'!AM8*Driver_Utilities -> 0 | AN33: ='Revenue Forecast'!AN8*Driver_Utilities -> 0 | AO33: ='Revenue Forecast'!AO8*Driver_Utilities -> 0 | AP33: ='Revenue Forecast'!AP8*Driver_Utilities -> 0 | AQ33: ='Revenue Forecast'!AQ8*Driver_Utilities -> 0 | AR33: ='Revenue Forecast'!AR8*Driver_Utilities -> 0 | AS33: ='Revenue Forecast'!AS8*Driver_Utilities -> 0 | AT33: ='Revenue Forecast'!AT8*Driver_Utilities -> 0 | ... BJ33: ='Revenue Forecast'!BJ8*Driver_Utilities -> 0
A34: Total Utilities | C34: =SUM(C29:C33) -> 0 | D34: =SUM(D29:D33) -> 0 | E34: =SUM(E29:E33) -> 0 | F34: =SUM(F29:F33) -> 0 | G34: =SUM(G29:G33) -> 0 | H34: =SUM(H29:H33) -> 0 | I34: =SUM(I29:I33) -> 0 | J34: =SUM(J29:J33) -> 0 | ... BJ34: =SUM(BJ29:BJ33) -> 0
A36: D&A
A37: D&A | B37: Unit 1 | C37: ='Historical Data'!C10 -> 0 | D37: ='Historical Data'!D10 -> 0 | E37: ='Historical Data'!E10 -> 0 | F37: ='Historical Data'!F10 -> 0 | G37: ='Historical Data'!G10 -> 0 | H37: ='Historical Data'!H10 -> 0 | I37: ='Historical Data'!I10 -> 0 | J37: ='Historical Data'!J10 -> 0 | ... AL37: ='Historical Data'!AL10 -> 0 | AM37: =AL37 -> 0 | AN37: =AM37 -> 0 | AO37: =AN37 -> 0 | AP37: =AO37 -> 0 | AQ37: =AP37 -> 0 | AR37: =AQ37 -> 0 | AS37: =AR37 -> 0 | AT37: =AS37 -> 0 | ... BJ37: =BI37 -> 0
A38: D&A | B38: Unit 2 | C38: ='Historical Data'!C18 -> 0 | D38: ='Historical Data'!D18 -> 0 | E38: ='Historical Data'!E18 -> 0 | F38: ='Historical Data'!F18 -> 0 | G38: ='Historical Data'!G18 -> 0 | H38: ='Historical Data'!H18 -> 0 | I38: ='Historical Data'!I18 -> 0 | J38: ='Historical Data'!J18 -> 0 | ... AL38: ='Historical Data'!AL18 -> 0 | AM38: =AL38 -> 0 | AN38: =AM38 -> 0 | AO38: =AN38 -> 0 | AP38: =AO38 -> 0 | AQ38: =AP38 -> 0 | AR38: =AQ38 -> 0 | AS38: =AR38 -> 0 | AT38: =AS38 -> 0 | ... BJ38: =BI38 -> 0
A39: D&A | B39: Unit 3 | C39: ='Historical Data'!C26 -> 0 | D39: ='Historical Data'!D26 -> 0 | E39: ='Historical Data'!E26 -> 0 | F39: ='Historical Data'!F26 -> 0 | G39: ='Historical Data'!G26 -> 0 | H39: ='Historical Data'!H26 -> 0 | I39: ='Historical Data'!I26 -> 0 | J39: ='Historical Data'!J26 -> 0 | ... AL39: ='Historical Data'!AL26 -> 0 | AM39: =AL39 -> 0 | AN39: =AM39 -> 0 | AO39: =AN39 -> 0 | AP39: =AO39 -> 0 | AQ39: =AP39 -> 0 | AR39: =AQ39 -> 0 | AS39: =AR39 -> 0 | AT39: =AS39 -> 0 | ... BJ39: =BI39 -> 0
A40: D&A | B40: Unit 4 | C40: ='Historical Data'!C34 -> 0 | D40: ='Historical Data'!D34 -> 0 | E40: ='Historical Data'!E34 -> 0 | F40: ='Historical Data'!F34 -> 0 | G40: ='Historical Data'!G34 -> 0 | H40: ='Historical Data'!H34 -> 0 | I40: ='Historical Data'!I34 -> 0 | J40: ='Historical Data'!J34 -> 0 | ... AL40: ='Historical Data'!AL34 -> 0 | AM40: =AL40 -> 0 | AN40: =AM40 -> 0 | AO40: =AN40 -> 0 | AP40: =AO40 -> 0 | AQ40: =AP40 -> 0 | AR40: =AQ40 -> 0 | AS40: =AR40 -> 0 | AT40: =AS40 -> 0 | ... BJ40: =BI40 -> 0
A41: D&A | B41: Unit 5 | C41: ='Historical Data'!C42 -> 0 | D41: ='Historical Data'!D42 -> 0 | E41: ='Historical Data'!E42 -> 0 | F41: ='Historical Data'!F42 -> 0 | G41: ='Historical Data'!G42 -> 0 | H41: ='Historical Data'!H42 -> 0 | I41: ='Historical Data'!I42 -> 0 | J41: ='Historical Data'!J42 -> 0 | ... AL41: ='Historical Data'!AL42 -> 0 | AM41: =AL41 -> 0 | AN41: =AM41 -> 0 | AO41: =AN41 -> 0 | AP41: =AO41 -> 0 | AQ41: =AP41 -> 0 | AR41: =AQ41 -> 0 | AS41: =AR41 -> 0 | AT41: =AS41 -> 0 | ... BJ41: =BI41 -> 0
A42: Total D&A | C42: =SUM(C37:C41) -> 0 | D42: =SUM(D37:D41) -> 0 | E42: =SUM(E37:E41) -> 0 | F42: =SUM(F37:F41) -> 0 | G42: =SUM(G37:G41) -> 0 | H42: =SUM(H37:H41) -> 0 | I42: =SUM(I37:I41) -> 0 | J42: =SUM(J37:J41) -> 0 | ... BJ42: =SUM(BJ37:BJ41) -> 0
A44: Other OpEx
A45: Other OpEx | B45: Unit 1 | C45: ='Historical Data'!C11 -> 0 | D45: ='Historical Data'!D11 -> 0 | E45: ='Historical Data'!E11 -> 0 | F45: ='Historical Data'!F11 -> 0 | G45: ='Historical Data'!G11 -> 0 | H45: ='Historical Data'!H11 -> 0 | I45: ='Historical Data'!I11 -> 0 | J45: ='Historical Data'!J11 -> 0 | ... AL45: ='Historical Data'!AL11 -> 0 | AM45: ='Revenue Forecast'!AM4*Driver_OtherOpEx -> 0 | AN45: ='Revenue Forecast'!AN4*Driver_OtherOpEx -> 0 | AO45: ='Revenue Forecast'!AO4*Driver_OtherOpEx -> 0 | AP45: ='Revenue Forecast'!AP4*Driver_OtherOpEx -> 0 | AQ45: ='Revenue Forecast'!AQ4*Driver_OtherOpEx -> 0 | AR45: ='Revenue Forecast'!AR4*Driver_OtherOpEx -> 0 | AS45: ='Revenue Forecast'!AS4*Driver_OtherOpEx -> 0 | AT45: ='Revenue Forecast'!AT4*Driver_OtherOpEx -> 0 | ... BJ45: ='Revenue Forecast'!BJ4*Driver_OtherOpEx -> 0
...

Sheet P&L Summary
A1: Consolidated P&L Statement
B2: 44197 | C2: 44228 | D2: 44256 | E2: 44287 | F2: 44317 | G2: 44348 | H2: 44378 | I2: 44409 | J2: 44440 | K2: 44470 | L2: 44501 | M2: 44531 | N2: 44562 | O2: 44593 | P2: 44621 | Q2: 44652 | R2: 44682 | S2: 44713 | T2: 44743 | U2: 44774 | V2: 44805 | W2: 44835 | X2: 44866 | Y2: 44896 | Z2: 44927 | AA2: 44958 | AB2: 44986 | AC2: 45017 | AD2: 45047 | AE2: 45078 | AF2: 45108 | AG2: 45139 | AH2: 45170 | AI2: 45200 | AJ2: 45231 | AK2: 45261 | AL2: 45292 | AM2: 45323 | AN2: 45352 | AO2: 45383 | AP2: 45413 | AQ2: 45444 | AR2: 45474 | AS2: 45505 | AT2: 45536 | AU2: 45566 | AV2: 45597 | AW2: 45627 | AX2: 45658 | AY2: 45689 | AZ2: 45717 | BA2: 45748 | BB2: 45778 | BC2: 45809 | BD2: 45839 | BE2: 45870 | BF2: 45901 | BG2: 45931 | BH2: 45962 | BI2: 45992
B3: Actual | C3: Actual | D3: Actual | E3: Actual | F3: Actual | G3: Actual | H3: Actual | I3: Actual | J3: Actual | K3: Actual | L3: Actual | M3: Actual | N3: Actual | O3: Actual | P3: Actual | Q3: Actual | R3: Actual | S3: Actual | T3: Actual | U3: Actual | V3: Actual | W3: Actual | X3: Actual | Y3: Actual | Z3: Actual | AA3: Actual | AB3: Actual | AC3: Actual | AD3: Actual | AE3: Actual | AF3: Actual | AG3: Actual | AH3: Actual | AI3: Actual | AJ3: Actual | AK3: Actual | AL3: Forecast | AM3: Forecast | AN3: Forecast | AO3: Forecast | AP3: Forecast | AQ3: Forecast | AR3: Forecast | AS3: Forecast | AT3: Forecast | AU3: Forecast | AV3: Forecast | AW3: Forecast | AX3: Forecast | AY3: Forecast | AZ3: Forecast | BA3: Forecast | BB3: Forecast | BC3: Forecast | BD3: Forecast | BE3: Forecast | BF3: Forecast | BG3: Forecast | BH3: Forecast | BI3: Forecast
A4: Net Revenue | B4: ='Revenue Forecast'!C9 -> 0 | C4: ='Revenue Forecast'!D9 -> 0 | D4: ='Revenue Forecast'!E9 -> 0 | E4: ='Revenue Forecast'!F9 -> 0 | F4: ='Revenue Forecast'!G9 -> 0 | G4: ='Revenue Forecast'!H9 -> 0 | H4: ='Revenue Forecast'!I9 -> 0 | I4: ='Revenue Forecast'!J9 -> 0 | ... BI4: ='Revenue Forecast'!BJ9 -> 0
A5: COGS | B5: ='COGS & Gross Margin'!C9 -> 0 | C5: ='COGS & Gross Margin'!D9 -> 0 | D5: ='COGS & Gross Margin'!E9 -> 0 | E5: ='COGS & Gross Margin'!F9 -> 0 | F5: ='COGS & Gross Margin'!G9 -> 0 | G5: ='COGS & Gross Margin'!H9 -> 0 | H5: ='COGS & Gross Margin'!I9 -> 0 | I5: ='COGS & Gross Margin'!J9 -> 0 | ... BI5: ='COGS & Gross Margin'!BJ9 -> 0
A6: Gross Profit | B6: ='COGS & Gross Margin'!C11 -> 0 | C6: ='COGS & Gross Margin'!D11 -> 0 | D6: ='COGS & Gross Margin'!E11 -> 0 | E6: ='COGS & Gross Margin'!F11 -> 0 | F6: ='COGS & Gross Margin'!G11 -> 0 | G6: ='COGS & Gross Margin'!H11 -> 0 | H6: ='COGS & Gross Margin'!I11 -> 0 | I6: ='COGS & Gross Margin'!J11 -> 0 | ... BI6: ='COGS & Gross Margin'!BJ11 -> 0
A7: Gross Margin % | B7: ='COGS & Gross Margin'!B12 -> 0 | C7: ='COGS & Gross Margin'!C12 -> 0 | D7: ='COGS & Gross Margin'!D12 -> 0 | E7: ='COGS & Gross Margin'!E12 -> 0 | F7: ='COGS & Gross Margin'!F12 -> 0 | G7: ='COGS & Gross Margin'!G12 -> 0 | H7: ='COGS & Gross Margin'!H12 -> 0 | I7: ='COGS & Gross Margin'!I12 -> 0 | ... BI7: ='COGS & Gross Margin'!BI12 -> 0
A9: Payroll | B9: ='OpEx'!C10 -> 0 | C9: ='OpEx'!D10 -> 0 | D9: ='OpEx'!E10 -> 0 | E9: ='OpEx'!F10 -> 0 | F9: ='OpEx'!G10 -> 0 | G9: ='OpEx'!H10 -> 0 | H9: ='OpEx'!I10 -> 0 | I9: ='OpEx'!J10 -> 0 | ... BI9: ='OpEx'!BJ10 -> 0
A10: Rent | B10: ='OpEx'!C18 -> 0 | C10: ='OpEx'!D18 -> 0 | D10: ='OpEx'!E18 -> 0 | E10: ='OpEx'!F18 -> 0 | F10: ='OpEx'!G18 -> 0 | G10: ='OpEx'!H18 -> 0 | H10: ='OpEx'!I18 -> 0 | I10: ='OpEx'!J18 -> 0 | ... BI10: ='OpEx'!BJ18 -> 0
A11: Marketing | B11: ='OpEx'!C26 -> 0 | C11: ='OpEx'!D26 -> 0 | D11: ='OpEx'!E26 -> 0 | E11: ='OpEx'!F26 -> 0 | F11: ='OpEx'!G26 -> 0 | G11: ='OpEx'!H26 -> 0 | H11: ='OpEx'!I26 -> 0 | I11: ='OpEx'!J26 -> 0 | ... BI11: ='OpEx'!BJ26 -> 0
A12: Utilities | B12: ='OpEx'!C34 -> 0 | C12: ='OpEx'!D34 -> 0 | D12: ='OpEx'!E34 -> 0 | E12: ='OpEx'!F34 -> 0 | F12: ='OpEx'!G34 -> 0 | G12: ='OpEx'!H34 -> 0 | H12: ='OpEx'!I34 -> 0 | I12: ='OpEx'!J34 -> 0 | ... BI12: ='OpEx'!BJ34 -> 0
A13: Other OpEx | B13: ='OpEx'!C50 -> 0 | C13: ='OpEx'!D50 -> 0 | D13: ='OpEx'!E50 -> 0 | E13: ='OpEx'!F50 -> 0 | F13: ='OpEx'!G50 -> 0 | G13: ='OpEx'!H50 -> 0 | H13: ='OpEx'!I50 -> 0 | I13: ='OpEx'!J50 -> 0 | ... BI13: ='OpEx'!BJ50 -> 0
A14: Total Operating Expenses | B14: ='OpEx'!C52 -> 0 | C14: ='OpEx'!D52 -> 0 | D14: ='OpEx'!E52 -> 0 | E14: ='OpEx'!F52 -> 0 | F14: ='OpEx'!G52 -> 0 | G14: ='OpEx'!H52 -> 0 | H14: ='OpEx'!I52 -> 0 | I14: ='OpEx'!J52 -> 0 | ... BI14: ='OpEx'!BJ52 -> 0
A16: EBITDA | B16: =B6-B14 -> 0 | C16: =C6-C14 -> 0 | D16: =D6-D14 -> 0 | E16: =E6-E14 -> 0 | F16: =F6-F14 -> 0 | G16: =G6-G14 -> 0 | H16: =H6-H14 -> 0 | I16: =I6-I14 -> 0 | ... BI16: =BI6-BI14 -> 0
A17: EBITDA Margin % | B17: =IFERROR(B16/B4, 0) -> 0 | C17: =IFERROR(C16/C4, 0) -> 0 | D17: =IFERROR(D16/D4, 0) -> 0 | E17: =IFERROR(E16/E4, 0) -> 0 | F17: =IFERROR(F16/F4, 0) -> 0 | G17: =IFERROR(G16/G4, 0) -> 0 | H17: =IFERROR(H16/H4, 0) -> 0 | I17: =IFERROR(I16/I4, 0) -> 0 | ... BI17: =IFERROR(BI16/BI4, 0) -> 0
A18: D&A | B18: ='OpEx'!C42 -> 0 | C18: ='OpEx'!D42 -> 0 | D18: ='OpEx'!E42 -> 0 | E18: ='OpEx'!F42 -> 0 | F18: ='OpEx'!G42 -> 0 | G18: ='OpEx'!H42 -> 0 | H18: ='OpEx'!I42 -> 0 | I18: ='OpEx'!J42 -> 0 | ... BI18: ='OpEx'!BJ42 -> 0
A19: Net Operating Income (NOI) | B19: =B16-B18 -> 0 | C19: =C16-C18 -> 0 | D19: =D16-D18 -> 0 | E19: =E16-E18 -> 0 | F19: =F16-F18 -> 0 | G19: =G16-G18 -> 0 | H19: =H16-H18 -> 0 | I19: =I16-I18 -> 0 | ... BI19: =BI16-BI18 -> 0

Sheet Variance Analysis
A1: Automated Variance Analysis Engine
A3: Select Month for Analysis: | B3: 45292
I4: Automated Variance Commentary
A5: P&L Line Item | B5: Actual | C5: Budget | D5: $ Var (BvA) | E5: % Var | F5: Prior Year | G5: $ Var (YoY) | H5: % Var
A6: Net Revenue | B6: =HLOOKUP($B$3, 'P&L Summary'!$B$2:$ZZ$100, 3, FALSE) -> 0 | C6: =HLOOKUP($B$3, 'P&L Summary'!$B$2:$ZZ$100, 3, FALSE) * 1.05 -> 0 | D6: =(1)*(B6-C6) -> 0 | E6: =IFERROR(D6/C6, 0) -> 0 | F6: =HLOOKUP(EDATE($B$3,-12), 'P&L Summary'!$B$2:$ZZ$100, 3, FALSE) -> 0 | G6: =(1)*(B6-F6) -> 0 | H6: =IFERROR(G6/F6, 0) -> 0 | I6: =IF(D6>=0, "🟢 Favorable: Revenue exceeded budget by "&TEXT(D6,"$#,##0")&" ("&TEXT(E6,"0.0%")&"), driven by outperformance in base units.", "🔴 Unfavorable: Revenue missed budget by "&TEXT(ABS(D6),"$#,##0")&" ("&TEXT(E6,"0.0%")&"). Review unit traffic.") -> 0
A7: COGS | B7: =HLOOKUP($B$3, 'P&L Summary'!$B$2:$ZZ$100, 4, FALSE) -> 0 | C7: =HLOOKUP($B$3, 'P&L Summary'!$B$2:$ZZ$100, 4, FALSE) * 1.05 -> 0 | D7: =(-1)*(B7-C7) -> 0 | E7: =IFERROR(D7/C7, 0) -> 0 | F7: =HLOOKUP(EDATE($B$3,-12), 'P&L Summary'!$B$2:$ZZ$100, 4, FALSE) -> 0 | G7: =(-1)*(B7-F7) -> 0 | H7: =IFERROR(G7/F7, 0) -> 0
A8: Gross Profit | B8: =HLOOKUP($B$3, 'P&L Summary'!$B$2:$ZZ$100, 5, FALSE) -> 0 | C8: =HLOOKUP($B$3, 'P&L Summary'!$B$2:$ZZ$100, 5, FALSE) * 1.05 -> 0 | D8: =(1)*(B8-C8) -> 0 | E8: =IFERROR(D8/C8, 0) -> 0 | F8: =HLOOKUP(EDATE($B$3,-12), 'P&L Summary'!$B$2:$ZZ$100, 5, FALSE) -> 0 | G8: =(1)*(B8-F8) -> 0 | H8: =IFERROR(G8/F8, 0) -> 0
A9: Total Operating Expenses | B9: =HLOOKUP($B$3, 'P&L Summary'!$B$2:$ZZ$100, 13, FALSE) -> 0 | C9: =HLOOKUP($B$3, 'P&L Summary'!$B$2:$ZZ$100, 13, FALSE) * 1.05 -> 0 | D9: =(-1)*(B9-C9) -> 0 | E9: =IFERROR(D9/C9, 0) -> 0 | F9: =HLOOKUP(EDATE($B$3,-12), 'P&L Summary'!$B$2:$ZZ$100, 13, FALSE) -> 0 | G9: =(-1)*(B9-F9) -> 0 | H9: =IFERROR(G9/F9, 0) -> 0
A10: EBITDA | B10: =HLOOKUP($B$3, 'P&L Summary'!$B$2:$ZZ$100, 15, FALSE) -> 0 | C10: =HLOOKUP($B$3, 'P&L Summary'!$B$2:$ZZ$100, 15, FALSE) * 1.05 -> 0 | D10: =(1)*(B10-C10) -> 0 | E10: =IFERROR(D10/C10, 0) -> 0 | F10: =HLOOKUP(EDATE($B$3,-12), 'P&L Summary'!$B$2:$ZZ$100, 15, FALSE) -> 0 | G10: =(1)*(B10-F10) -> 0 | H10: =IFERROR(G10/F10, 0) -> 0 | I10: =IF(D10>=0, "🟢 Favorable: EBITDA is ahead of budget by "&TEXT(D10,"$#,##0")&" due to tight OpEx control.", "🔴 Unfavorable: EBITDA underperformed by "&TEXT(ABS(D10),"$#,##0")&". Consider cost optimization options.") -> 0
A11: Net Operating Income (NOI) | B11: =HLOOKUP($B$3, 'P&L Summary'!$B$2:$ZZ$100, 18, FALSE) -> 0 | C11: =HLOOKUP($B$3, 'P&L Summary'!$B$2:$ZZ$100, 18, FALSE) * 1.05 -> 0 | D11: =(1)*(B11-C11) -> 0 | E11: =IFERROR(D11/C11, 0) -> 0 | F11: =HLOOKUP(EDATE($B$3,-12), 'P&L Summary'!$B$2:$ZZ$100, 18, FALSE) -> 0 | G11: =(1)*(B11-F11) -> 0 | H11: =IFERROR(G11/F11, 0) -> 0

Sheet Model Audit
A1: Model Audit & Health Checks
A3: Audit Check | B3: Status | C3: Variance
A4: Revenue Rollup matches Unit Sum | B4: =IF(ABS(C4)<1, "Pass", "FAIL") -> 0 | C4: =SUM('Revenue Forecast'!B9:ZZ9)-SUM('Revenue Forecast'!B4:ZZ8) -> 0
A5: COGS matches Profile % | B5: =IF(ABS(C5)<1, "Pass", "FAIL") -> 0 | C5: =SUM('COGS & Gross Margin'!B9:ZZ9) - (SUM('Revenue Forecast'!B9:ZZ9)*Driver_COGS) -> 0
A8: Forecast Accuracy (Historical Backtest)
A10: Calculates absolute percentage error on back-tested held-out data (6 mo).
A11: Model MAPE: | B11: 0.045 | C11: (>94% Target Achieved)
